Workbook

Sheet 00_Portada
B2: GENTIA
B5: PLAN DE IMPLEMENTACIÓN DEL ERP
B7: Hoja de ruta integral, control de avance y evidencia de aceptación
B9: Proyecto | C9: Implementación ERP GENTIA
B10: Versión | C10: 1.0
B11: Fecha de elaboración | C11: 46323.75
B12: Inicio base editable | C12: 46328.75
B13: Salida objetivo editable | C13: 46496.75
B14: Estrategia sugerida | C14: Rollout por olas: piloto → filiales prioritarias → resto del grupo
B15: Responsables | C15: Roles sugeridos; el cliente debe confirmar nombres y disponibilidad
B16: Subsidiarias incluidas | C16: 35
B17: Actividades detalladas | C17: 280
B18: Referencia | C18: Implementacion 2026 - GENTIA.xlsx
B21: SUPUESTOS EDITABLES Y REGLAS DE USO
B22: 1. Confirme las fechas, responsables y olas antes de aprobar la línea base.
B23: 2. Actualice Estado y % avance; el Dashboard se recalcula al abrir Excel.
B24: 3. No sobrescriba fórmulas de Duración, Semáforo, diferencias ni porcentajes.
B25: 4. Go-Live exige Mayor cuadrado, auxiliares conciliados en 0,00, UAT aprobada y cero defectos críticos.
B26: 5. Adjunte evidencia verificable para cada actividad, carga, prueba, hito y decisión.

Sheet 01_Dashboard
A1: DASHBOARD EJECUTIVO
A2: Indicadores dinámicos de avance, pruebas, riesgos y filiales.
A5: Actividades | C5: Completadas | E5: Avance | G5: Vencidas
A6: =COUNTA('02_Plan_Maestro'!$A$6:$A$285) -> 280 | C6: =COUNTIF('02_Plan_Maestro'!$V$6:$V$285,"Completada") -> 0 | E6: =IFERROR(SUMPRODUCT('02_Plan_Maestro'!$P$6:$P$285,'02_Plan_Maestro'!$W$6:$W$285)/SUM('02_Plan_Maestro'!$P$6:$P$285),0) -> 0 | G6: =COUNTIFS('02_Plan_Maestro'!$R$6:$R$285,"<"&TODAY(),'02_Plan_Maestro'!$V$6:$V$285,"<>Completada") -> 0
A9: Bloqueadas | C9: Riesgos críticos | E9: UAT | G9: Preparación filiales
A10: =COUNTIF('02_Plan_Maestro'!$V$6:$V$285,"Bloqueada") -> 0 | C10: =COUNTIFS('09_Riesgos'!$L$6:$L$40,">=15",'09_Riesgos'!$N$6:$N$40,"<>Cerrado") -> 0 | E10: =IFERROR(COUNTIF('06_Pruebas_UAT'!$K$6:$K$300,"Aprobado")/236,0) -> 0 | G10: =IFERROR(AVERAGE('03_Rollout_Filiales'!$M$6:$M$40),0) -> 0
A14: AVANCE POR MÓDULO
A15: Módulo | B15: Total | C15: Completadas | D15: Avance | E15: Vencidas | G15: Módulo | H15: Total | I15: Completadas | J15: Avance
A16: Gobierno del proyecto | B16: =COUNTIF('02_Plan_Maestro'!$C$6:$C$285,A16) -> 0 | C16: =COUNTIFS('02_Plan_Maestro'!$C$6:$C$285,A16,'02_Plan_Maestro'!$V$6:$V$285,"Completada") -> 0 | D16: =IFERROR(SUMPRODUCT(('02_Plan_Maestro'!$C$6:$C$285=A16)*'02_Plan_Maestro'!$P$6:$P$285*'02_Plan_Maestro'!$W$6:$W$285)/SUMIF('02_Plan_Maestro'!$C$6:$C$285,A16,'02_Plan_Maestro'!$P$6:$P$285),0) -> 0 | E16: =COUNTIFS('02_Plan_Maestro'!$C$6:$C$285,A16,'02_Plan_Maestro'!$R$6:$R$285,"<"&TODAY(),'02_Plan_Maestro'!$V$6:$V$285,"<>Completada") -> 0 | G16: Infraestructura y plataforma | H16: =COUNTIF('02_Plan_Maestro'!$C$6:$C$285,G16) -> 0 | I16: =COUNTIFS('02_Plan_Maestro'!$C$6:$C$285,G16,'02_Plan_Maestro'!$V$6:$V$285,"Completada") -> 0 | J16: =IFERROR(SUMPRODUCT(('02_Plan_Maestro'!$C$6:$C$285=G16)*'02_Plan_Maestro'!$P$6:$P$285*'02_Plan_Maestro'!$W$6:$W$285)/SUMIF('02_Plan_Maestro'!$C$6:$C$285,G16,'02_Plan_Maestro'!$P$6:$P$285),0) -> 0
A17: CORE | B17: =COUNTIF('02_Plan_Maestro'!$C$6:$C$285,A17) -> 0 | C17: =COUNTIFS('02_Plan_Maestro'!$C$6:$C$285,A17,'02_Plan_Maestro'!$V$6:$V$285,"Completada") -> 0 | D17: =IFERROR(SUMPRODUCT(('02_Plan_Maestro'!$C$6:$C$285=A17)*'02_Plan_Maestro'!$P$6:$P$285*'02_Plan_Maestro'!$W$6:$W$285)/SUMIF('02_Plan_Maestro'!$C$6:$C$285,A17,'02_Plan_Maestro'!$P$6:$P$285),0) -> 0 | E17: =COUNTIFS('02_Plan_Maestro'!$C$6:$C$285,A17,'02_Plan_Maestro'!$R$6:$R$285,"<"&TODAY(),'02_Plan_Maestro'!$V$6:$V$285,"<>Completada") -> 0 | G17: Organización | H17: =COUNTIF('02_Plan_Maestro'!$C$6:$C$285,G17) -> 0 | I17: =COUNTIFS('02_Plan_Maestro'!$C$6:$C$285,G17,'02_Plan_Maestro'!$V$6:$V$285,"Completada") -> 0 | J17: =IFERROR(SUMPRODUCT(('02_Plan_Maestro'!$C$6:$C$285=G17)*'02_Plan_Maestro'!$P$6:$P$285*'02_Plan_Maestro'!$W$6:$W$285)/SUMIF('02_Plan_Maestro'!$C$6:$C$285,G17,'02_Plan_Maestro'!$P$6:$P$285),0) -> 0
A18: Seguridad | B18: =COUNTIF('02_Plan_Maestro'!$C$6:$C$285,A18) -> 0 | C18: =COUNTIFS('02_Plan_Maestro'!$C$6:$C$285,A18,'02_Plan_Maestro'!$V$6:$V$285,"Completada") -> 0 | D18: =IFERROR(SUMPRODUCT(('02_Plan_Maestro'!$C$6:$C$285=A18)*'02_Plan_Maestro'!$P$6:$P$285*'02_Plan_Maestro'!$W$6:$W$285)/SUMIF('02_Plan_Maestro'!$C$6:$C$285,A18,'02_Plan_Maestro'!$P$6:$P$285),0) -> 0 | E18: =COUNTIFS('02_Plan_Maestro'!$C$6:$C$285,A18,'02_Plan_Maestro'!$R$6:$R$285,"<"&TODAY(),'02_Plan_Maestro'!$V$6:$V$285,"<>Completada") -> 0 | G18: Configuración transversal | H18: =COUNTIF('02_Plan_Maestro'!$C$6:$C$285,G18) -> 0 | I18: =COUNTIFS('02_Plan_Maestro'!$C$6:$C$285,G18,'02_Plan_Maestro'!$V$6:$V$285,"Completada") -> 0 | J18: =IFERROR(SUMPRODUCT(('02_Plan_Maestro'!$C$6:$C$285=G18)*'02_Plan_Maestro'!$P$6:$P$285*'02_Plan_Maestro'!$W$6:$W$285)/SUMIF('02_Plan_Maestro'!$C$6:$C$285,G18,'02_Plan_Maestro'!$P$6:$P$285),0) -> 0
A19: Contabilidad | B19: =COUNTIF('02_Plan_Maestro'!$C$6:$C$285,A19) -> 0 | C19: =COUNTIFS('02_Plan_Maestro'!$C$6:$C$285,A19,'02_Plan_Maestro'!$V$6:$V$285,"Completada") -> 0 | D19: =IFERROR(SUMPRODUCT(('02_Plan_Maestro'!$C$6:$C$285=A19)*'02_Plan_Maestro'!$P$6:$P$285*'02_Plan_Maestro'!$W$6:$W$285)/SUMIF('02_Plan_Maestro'!$C$6:$C$285,A19,'02_Plan_Maestro'!$P$6:$P$285),0) -> 0 | E19: =COUNTIFS('02_Plan_Maestro'!$C$6:$C$285,A19,'02_Plan_Maestro'!$R$6:$R$285,"<"&TODAY(),'02_Plan_Maestro'!$V$6:$V$285,"<>Completada") -> 0 | G19: Motor de transacciones | H19: =COUNTIF('02_Plan_Maestro'!$C$6:$C$285,G19) -> 0 | I19: =COUNTIFS('02_Plan_Maestro'!$C$6:$C$285,G19,'02_Plan_Maestro'!$V$6:$V$285,"Completada") -> 0 | J19: =IFERROR(SUMPRODUCT(('02_Plan_Maestro'!$C$6:$C$285=G19)*'02_Plan_Maestro'!$P$6:$P$285*'02_Plan_Maestro'!$W$6:$W$285)/SUMIF('02_Plan_Maestro'!$C$6:$C$285,G19,'02_Plan_Maestro'!$P$6:$P$285),0) -> 0
A20: Entidades | B20: =COUNTIF('02_Plan_Maestro'!$C$6:$C$285,A20) -> 0 | C20: =COUNTIFS('02_Plan_Maestro'!$C$6:$C$285,A20,'02_Plan_Maestro'!$V$6:$V$285,"Completada") -> 0 | D20: =IFERROR(SUMPRODUCT(('02_Plan_Maestro'!$C$6:$C$285=A20)*'02_Plan_Maestro'!$P$6:$P$285*'02_Plan_Maestro'!$W$6:$W$285)/SUMIF('02_Plan_Maestro'!$C$6:$C$285,A20,'02_Plan_Maestro'!$P$6:$P$285),0) -> 0 | E20: =COUNTIFS('02_Plan_Maestro'!$C$6:$C$285,A20,'02_Plan_Maestro'!$R$6:$R$285,"<"&TODAY(),'02_Plan_Maestro'!$V$6:$V$285,"<>Completada") -> 0 | G20: Ventas y Cuentas por Cobrar | H20: =COUNTIF('02_Plan_Maestro'!$C$6:$C$285,G20) -> 0 | I20: =COUNTIFS('02_Plan_Maestro'!$C$6:$C$285,G20,'02_Plan_Maestro'!$V$6:$V$285,"Completada") -> 0 | J20: =IFERROR(SUMPRODUCT(('02_Plan_Maestro'!$C$6:$C$285=G20)*'02_Plan_Maestro'!$P$6:$P$285*'02_Plan_Maestro'!$W$6:$W$285)/SUMIF('02_Plan_Maestro'!$C$6:$C$285,G20,'02_Plan_Maestro'!$P$6:$P$285),0) -> 0
A21: Compras y Cuentas por Pagar | B21: =COUNTIF('02_Plan_Maestro'!$C$6:$C$285,A21) -> 0 | C21: =COUNTIFS('02_Plan_Maestro'!$C$6:$C$285,A21,'02_Plan_Maestro'!$V$6:$V$285,"Completada") -> 0 | D21: =IFERROR(SUMPRODUCT(('02_Plan_Maestro'!$C$6:$C$285=A21)*'02_Plan_Maestro'!$P$6:$P$285*'02_Plan_Maestro'!$W$6:$W$285)/SUMIF('02_Plan_Maestro'!$C$6:$C$285,A21,'02_Plan_Maestro'!$P$6:$P$285),0) -> 0 | E21: =COUNTIFS('02_Plan_Maestro'!$C$6:$C$285,A21,'02_Plan_Maestro'!$R$6:$R$285,"<"&TODAY(),'02_Plan_Maestro'!$V$6:$V$285,"<>Completada") -> 0 | G21: Gastos | H21: =COUNTIF('02_Plan_Maestro'!$C$6:$C$285,G21) -> 0 | I21: =COUNTIFS('02_Plan_Maestro'!$C$6:$C$285,G21,'02_Plan_Maestro'!$V$6:$V$285,"Completada") -> 0 | J21: =IFERROR(SUMPRODUCT(('02_Plan_Maestro'!$C$6:$C$285=G21)*'02_Plan_Maestro'!$P$6:$P$285*'02_Plan_Maestro'!$W$6:$W$285)/SUMIF('02_Plan_Maestro'!$C$6:$C$285,G21,'02_Plan_Maestro'!$P$6:$P$285),0) -> 0
A22: Workflow y aprobaciones | B22: =COUNTIF('02_Plan_Maestro'!$C$6:$C$285,A22) -> 0 | C22: =COUNTIFS('02_Plan_Maestro'!$C$6:$C$285,A22,'02_Plan_Maestro'!$V$6:$V$285,"Completada") -> 0 | D22: =IFERROR(SUMPRODUCT(('02_Plan_Maestro'!$C$6:$C$285=A22)*'02_Plan_Maestro'!$P$6:$P$285*'02_Plan_Maestro'!$W$6:$W$285)/SUMIF('02_Plan_Maestro'!$C$6:$C$285,A22,'02_Plan_Maestro'!$P$6:$P$285),0) -> 0 | E22: =COUNTIFS('02_Plan_Maestro'!$C$6:$C$285,A22,'02_Plan_Maestro'!$R$6:$R$285,"<"&TODAY(),'02_Plan_Maestro'!$V$6:$V$285,"<>Completada") -> 0 | G22: Bancos | H22: =COUNTIF('02_Plan_Maestro'!$C$6:$C$285,G22) -> 0 | I22: =COUNTIFS('02_Plan_Maestro'!$C$6:$C$285,G22,'02_Plan_Maestro'!$V$6:$V$285,"Completada") -> 0 | J22: =IFERROR(SUMPRODUCT(('02_Plan_Maestro'!$C$6:$C$285=G22)*'02_Plan_Maestro'!$P$6:$P$285*'02_Plan_Maestro'!$W$6:$W$285)/SUMIF('02_Plan_Maestro'!$C$6:$C$285,G22,'02_Plan_Maestro'!$P$6:$P$285),0) -> 0
A23: Tesorería | B23: =COUNTIF('02_Plan_Maestro'!$C$6:$C$285,A23) -> 0 | C23: =COUNTIFS('02_Plan_Maestro'!$C$6:$C$285,A23,'02_Plan_Maestro'!$V$6:$V$285,"Completada") -> 0 | D23: =IFERROR(SUMPRODUCT(('02_Plan_Maestro'!$C$6:$C$285=A23)*'02_Plan_Maestro'!$P$6:$P$285*'02_Plan_Maestro'!$W$6:$W$285)/SUMIF('02_Plan_Maestro'!$C$6:$C$285,A23,'02_Plan_Maestro'!$P$6:$P$285),0) -> 0 | E23: =COUNTIFS('02_Plan_Maestro'!$C$6:$C$285,A23,'02_Plan_Maestro'!$R$6:$R$285,"<"&TODAY(),'02_Plan_Maestro'!$V$6:$V$285,"<>Completada") -> 0 | G23: Activos Fijos | H23: =COUNTIF('02_Plan_Maestro'!$C$6:$C$285,G23) -> 0 | I23: =COUNTIFS('02_Plan_Maestro'!$C$6:$C$285,G23,'02_Plan_Maestro'!$V$6:$V$285,"Completada") -> 0 | J23: =IFERROR(SUMPRODUCT(('02_Plan_Maestro'!$C$6:$C$285=G23)*'02_Plan_Maestro'!$P$6:$P$285*'02_Plan_Maestro'!$W$6:$W$285)/SUMIF('02_Plan_Maestro'!$C$6:$C$285,G23,'02_Plan_Maestro'!$P$6:$P$285),0) -> 0
A24: Inventario | B24: =COUNTIF('02_Plan_Maestro'!$C$6:$C$285,A24) -> 0 | C24: =COUNTIFS('02_Plan_Maestro'!$C$6:$C$285,A24,'02_Plan_Maestro'!$V$6:$V$285,"Completada") -> 0 | D24: =IFERROR(SUMPRODUCT(('02_Plan_Maestro'!$C$6:$C$285=A24)*'02_Plan_Maestro'!$P$6:$P$285*'02_Plan_Maestro'!$W$6:$W$285)/SUMIF('02_Plan_Maestro'!$C$6:$C$285,A24,'02_Plan_Maestro'!$P$6:$P$285),0) -> 0 | E24: =COUNTIFS('02_Plan_Maestro'!$C$6:$C$285,A24,'02_Plan_Maestro'!$R$6:$R$285,"<"&TODAY(),'02_Plan_Maestro'!$V$6:$V$285,"<>Completada") -> 0 | G24: Fiscal | H24: =COUNTIF('02_Plan_Maestro'!$C$6:$C$285,G24) -> 0 | I24: =COUNTIFS('02_Plan_Maestro'!$C$6:$C$285,G24,'02_Plan_Maestro'!$V$6:$V$285,"Completada") -> 0 | J24: =IFERROR(SUMPRODUCT(('02_Plan_Maestro'!$C$6:$C$285=G24)*'02_Plan_Maestro'!$P$6:$P$285*'02_Plan_Maestro'!$W$6:$W$285)/SUMIF('02_Plan_Maestro'!$C$6:$C$285,G24,'02_Plan_Maestro'!$P$6:$P$285),0) -> 0
A25: Intercompany y Consolidación | B25: =COUNTIF('02_Plan_Maestro'!$C$6:$C$285,A25) -> 0 | C25: =COUNTIFS('02_Plan_Maestro'!$C$6:$C$285,A25,'02_Plan_Maestro'!$V$6:$V$285,"Completada") -> 0 | D25: =IFERROR(SUMPRODUCT(('02_Plan_Maestro'!$C$6:$C$285=A25)*'02_Plan_Maestro'!$P$6:$P$285*'02_Plan_Maestro'!$W$6:$W$285)/SUMIF('02_Plan_Maestro'!$C$6:$C$285,A25,'02_Plan_Maestro'!$P$6:$P$285),0) -> 0 | E25: =COUNTIFS('02_Plan_Maestro'!$C$6:$C$285,A25,'02_Plan_Maestro'!$R$6:$R$285,"<"&TODAY(),'02_Plan_Maestro'!$V$6:$V$285,"<>Completada") -> 0 | G25: Documentos | H25: =COUNTIF('02_Plan_Maestro'!$C$6:$C$285,G25) -> 0 | I25: =COUNTIFS('02_Plan_Maestro'!$C$6:$C$285,G25,'02_Plan_Maestro'!$V$6:$V$285,"Completada") -> 0 | J25: =IFERROR(SUMPRODUCT(('02_Plan_Maestro'!$C$6:$C$285=G25)*'02_Plan_Maestro'!$P$6:$P$285*'02_Plan_Maestro'!$W$6:$W$285)/SUMIF('02_Plan_Maestro'!$C$6:$C$285,G25,'02_Plan_Maestro'!$P$6:$P$285),0) -> 0
A26: Auditoría | B26: =COUNTIF('02_Plan_Maestro'!$C$6:$C$285,A26) -> 0 | C26: =COUNTIFS('02_Plan_Maestro'!$C$6:$C$285,A26,'02_Plan_Maestro'!$V$6:$V$285,"Completada") -> 0 | D26: =IFERROR(SUMPRODUCT(('02_Plan_Maestro'!$C$6:$C$285=A26)*'02_Plan_Maestro'!$P$6:$P$285*'02_Plan_Maestro'!$W$6:$W$285)/SUMIF('02_Plan_Maestro'!$C$6:$C$285,A26,'02_Plan_Maestro'!$P$6:$P$285),0) -> 0 | E26: =COUNTIFS('02_Plan_Maestro'!$C$6:$C$285,A26,'02_Plan_Maestro'!$R$6:$R$285,"<"&TODAY(),'02_Plan_Maestro'!$V$6:$V$285,"<>Completada") -> 0 | G26: Informes | H26: =COUNTIF('02_Plan_Maestro'!$C$6:$C$285,G26) -> 0 | I26: =COUNTIFS('02_Plan_Maestro'!$C$6:$C$285,G26,'02_Plan_Maestro'!$V$6:$V$285,"Completada") -> 0 | J26: =IFERROR(SUMPRODUCT(('02_Plan_Maestro'!$C$6:$C$285=G26)*'02_Plan_Maestro'!$P$6:$P$285*'02_Plan_Maestro'!$W$6:$W$285)/SUMIF('02_Plan_Maestro'!$C$6:$C$285,G26,'02_Plan_Maestro'!$P$6:$P$285),0) -> 0
A27: IA (opcional) | B27: =COUNTIF('02_Plan_Maestro'!$C$6:$C$285,A27) -> 0 | C27: =COUNTIFS('02_Plan_Maestro'!$C$6:$C$285,A27,'02_Plan_Maestro'!$V$6:$V$285,"Completada") -> 0 | D27: =IFERROR(SUMPRODUCT(('02_Plan_Maestro'!$C$6:$C$285=A27)*'02_Plan_Maestro'!$P$6:$P$285*'02_Plan_Maestro'!$W$6:$W$285)/SUMIF('02_Plan_Maestro'!$C$6:$C$285,A27,'02_Plan_Maestro'!$P$6:$P$285),0) -> 0 | E27: =COUNTIFS('02_Plan_Maestro'!$C$6:$C$285,A27,'02_Plan_Maestro'!$R$6:$R$285,"<"&TODAY(),'02_Plan_Maestro'!$V$6:$V$285,"<>Completada") -> 0 | G27: Migración de datos | H27: =COUNTIF('02_Plan_Maestro'!$C$6:$C$285,G27) -> 0 | I27: =COUNTIFS('02_Plan_Maestro'!$C$6:$C$285,G27,'02_Plan_Maestro'!$V$6:$V$285,"Completada") -> 0 | J27: =IFERROR(SUMPRODUCT(('02_Plan_Maestro'!$C$6:$C$285=G27)*'02_Plan_Maestro'!$P$6:$P$285*'02_Plan_Maestro'!$W$6:$W$285)/SUMIF('02_Plan_Maestro'!$C$6:$C$285,G27,'02_Plan_Maestro'!$P$6:$P$285),0) -> 0
A28: Pruebas formación y salida | B28: =COUNTIF('02_Plan_Maestro'!$C$6:$C$285,A28) -> 0 | C28: =COUNTIFS('02_Plan_Maestro'!$C$6:$C$285,A28,'02_Plan_Maestro'!$V$6:$V$285,"Completada") -> 0 | D28: =IFERROR(SUMPRODUCT(('02_Plan_Maestro'!$C$6:$C$285=A28)*'02_Plan_Maestro'!$P$6:$P$285*'02_Plan_Maestro'!$W$6:$W$285)/SUMIF('02_Plan_Maestro'!$C$6:$C$285,A28,'02_Plan_Maestro'!$P$6:$P$285),0) -> 0 | E28: =COUNTIFS('02_Plan_Maestro'!$C$6:$C$285,A28,'02_Plan_Maestro'!$R$6:$R$285,"<"&TODAY(),'02_Plan_Maestro'!$V$6:$V$285,"<>Completada") -> 0

Sheet 02_Plan_Maestro
A1: PLAN MAESTRO DE IMPLEMENTACIÓN
A2: Actualice Estado y % avance. Duración y Semáforo son fórmulas.
A5: ID | B5: Fase | C5: Módulo | D5: Submódulo / proceso | E5: Actividad | F5: Detalle paso a paso | G5: Entregable | H5: Criterio de aceptación | I5: Evidencia requerida | J5: Alcance / filiales | K5: Responsable GENTIA | L5: Responsable cliente | M5: Predecesora | N5: Dependencia | O5: Prioridad | P5: Peso | Q5: Inicio plan | R5: Fin plan | S5: Duración hábil | T5: Inicio real | U5: Fin real | V5: Estado | W5: % avance | X5: Semáforo | Y5: Observaciones
A6: IMP-001 | B6: 1. Gobierno y preparación | C6: Gobierno del proyecto | D6: Acta de constitución y criterios de éxito | E6: Definir y aprobar: Acta de constitución y criterios de éxito | F6: 1) Convocar responsables de Acta de constitución y criterios de éxito. 2) Acordar alcance, fechas y dependencias. 3) Documentar decisión y responsable. 4) Obtener aprobación formal. 5) Archivar evidencia. | G6: Acta de constitución y criterios de éxito: configuración, evidencia y acta | H6: Acta de constitución y criterios de éxito documentado con responsable, fecha y aprobación formal. | I6: Capturas, archivo de prueba, conciliación y aprobación | J6: Todas las filiales / ajustar por ola | K6: Director de proyecto | L6: Patrocinador ejecutivo | N6: Prerrequisitos del módulo | O6: Alta | P6: 2 | Q6: 46328.75 | R6: 46331.75 | S6: =NETWORKDAYS(Q6,R6) -> 4 | V6: No iniciada | W6: 0 | X6: =IF(OR(V6="Completada",V6="No aplica"),"VERDE",IF(V6="Bloqueada","ROJO",IF(R6<TODAY(),"ROJO",IF(AND(R6-TODAY()<=7,W6<1),"AMARILLO","GRIS")))) -> GRIS
A7: IMP-002 | B7: 1. Gobierno y preparación | C7: Gobierno del proyecto | D7: Alcance por país, filial, módulo y proceso | E7: Definir y aprobar: Alcance por país, filial, módulo y proceso | F7: 1) Convocar responsables de Alcance por país, filial, módulo y proceso. 2) Acordar alcance, fechas y dependencias. 3) Documentar decisión y responsable. 4) Obtener aprobación formal. 5) Archivar evidencia. | G7: Alcance por país, filial, módulo y proceso: configuración, evidencia y acta | H7: Alcance por país, filial, módulo y proceso documentado con responsable, fecha y aprobación formal. | I7: Capturas, archivo de prueba, conciliación y aprobación | J7: Todas las filiales / ajustar por ola | K7: Director de proyecto | L7: Patrocinador ejecutivo | M7: IMP-001 | N7: Finalizar IMP-001 | O7: Alta | P7: 2 | Q7: 46332.75 | R7: 46336.75 | S7: =NETWORKDAYS(Q7,R7) -> 3 | V7: No iniciada | W7: 0 | X7: =IF(OR(V7="Completada",V7="No aplica"),"VERDE",IF(V7="Bloqueada","ROJO",IF(R7<TODAY(),"ROJO",IF(AND(R7-TODAY()<=7,W7<1),"AMARILLO","GRIS")))) -> GRIS
A8: IMP-003 | B8: 1. Gobierno y preparación | C8: Gobierno del proyecto | D8: Estrategia de rollout por olas | E8: Definir y aprobar: Estrategia de rollout por olas | F8: 1) Convocar responsables de Estrategia de rollout por olas. 2) Acordar alcance, fechas y dependencias. 3) Documentar decisión y responsable. 4) Obtener aprobación formal. 5) Archivar evidencia. | G8: Estrategia de rollout por olas: configuración, evidencia y acta | H8: Estrategia de rollout por olas documentado con responsable, fecha y aprobación formal. | I8: Capturas, archivo de prueba, conciliación y aprobación | J8: Todas las filiales / ajustar por ola | K8: Director de proyecto | L8: Patrocinador ejecutivo | M8: IMP-002 | N8: Finalizar IMP-002 | O8: Media | P8: 1 | Q8: 46337.75 | R8: 46339.75 | S8: =NETWORKDAYS(Q8,R8) -> 3 | V8: No iniciada | W8: 0 | X8: =IF(OR(V8="Completada",V8="No aplica"),"VERDE",IF(V8="Bloqueada","ROJO",IF(R8<TODAY(),"ROJO",IF(AND(R8-TODAY()<=7,W8<1),"AMARILLO","GRIS")))) -> GRIS
A9: IMP-004 | B9: 1. Gobierno y preparación | C9: Gobierno del proyecto | D9: RACI y disponibilidad de responsables | E9: Definir y aprobar: RACI y disponibilidad de responsables | F9: 1) Convocar responsables de RACI y disponibilidad de responsables. 2) Acordar alcance, fechas y dependencias. 3) Documentar decisión y responsable. 4) Obtener aprobación formal. 5) Archivar evidencia. | G9: RACI y disponibilidad de responsables: configuración, evidencia y acta | H9: RACI y disponibilidad de responsables documentado con responsable, fecha y aprobación formal. | I9: Capturas, archivo de prueba, conciliación y aprobación | J9: Todas las filiales / ajustar por ola | K9: Director de proyecto | L9: Patrocinador ejecutivo | M9: IMP-003 | N9: Finalizar IMP-003 | O9: Media | P9: 1 | Q9: 46342.75 | R9: 46345.75 | S9: =NETWORKDAYS(Q9,R9) -> 4 | V9: No iniciada | W9: 0 | X9: =IF(OR(V9="Completada",V9="No aplica"),"VERDE",IF(V9="Bloqueada","ROJO",IF(R9<TODAY(),"ROJO",IF(AND(R9-TODAY()<=7,W9<1),"AMARILLO","GRIS")))) -> GRIS
A10: IMP-005 | B10: 1. Gobierno y preparación | C10: Gobierno del proyecto | D10: Calendario de comités y comunicaciones | E10: Definir y aprobar: Calendario de comités y comunicaciones | F10: 1) Convocar responsables de Calendario de comités y comunicaciones. 2) Acordar alcance, fechas y dependencias. 3) Documentar decisión y responsable. 4) Obtener aprobación formal. 5) Archivar evidencia. | G10: Calendario de comités y comunicaciones: configuración, evidencia y acta | H10: Calendario de comités y comunicaciones documentado con responsable, fecha y aprobación formal. | I10: Capturas, archivo de prueba, conciliación y aprobación | J10: Todas las filiales / ajustar por ola | K10: Director de proyecto | L10: Patrocinador ejecutivo | M10: IMP-004 | N10: Finalizar IMP-004 | O10: Media | P10: 1 | Q10: 46346.75 | R10: 46350.75 | S10: =NETWORKDAYS(Q10,R10) -> 3 | V10: No iniciada | W10: 0 | X10: =IF(OR(V10="Completada",V10="No aplica"),"VERDE",IF(V10="Bloqueada","ROJO",IF(R10<TODAY(),"ROJO",IF(AND(R10-TODAY()<=7,W10<1),"AMARILLO","GRIS")))) -> GRIS
A11: IMP-006 | B11: 1. Gobierno y preparación | C11: Gobierno del proyecto | D11: Registro de riesgos, incidencias y decisiones | E11: Definir y aprobar: Registro de riesgos, incidencias y decisiones | F11: 1) Convocar responsables de Registro de riesgos, incidencias y decisiones. 2) Acordar alcance, fechas y dependencias. 3) Documentar decisión y responsable. 4) Obtener aprobación formal. 5) Archivar evidencia. | G11: Registro de riesgos, incidencias y decisiones: configuración, evidencia y acta | H11: Registro de riesgos, incidencias y decisiones documentado con responsable, fecha y aprobación formal. | I11: Capturas, archivo de prueba, conciliación y aprobación | J11: Todas las filiales / ajustar por ola | K11: Director de proyecto | L11: Patrocinador ejecutivo | M11: IMP-005 | N11: Finalizar IMP-005 | O11: Media | P11: 1 | Q11: 46351.75 | R11: 46353.75 | S11: =NETWORKDAYS(Q11,R11) -> 3 | V11: No iniciada | W11: 0 | X11: =IF(OR(V11="Completada",V11="No aplica"),"VERDE",IF(V11="Bloqueada","ROJO",IF(R11<TODAY(),"ROJO",IF(AND(R11-TODAY()<=7,W11<1),"AMARILLO","GRIS")))) -> GRIS
A12: IMP-007 | B12: 1. Gobierno y preparación | C12: Gobierno del proyecto | D12: Control de cambios de alcance | E12: Definir y aprobar: Control de cambios de alcance | F12: 1) Convocar responsables de Control de cambios de alcance. 2) Acordar alcance, fechas y dependencias. 3) Documentar decisión y responsable. 4) Obtener aprobación formal. 5) Archivar evidencia. | G12: Control de cambios de alcance: configuración, evidencia y acta | H12: Control de cambios de alcance documentado con responsable, fecha y aprobación formal. | I12: Capturas, archivo de prueba, conciliación y aprobación | J12: Todas las filiales / ajustar por ola | K12: Director de proyecto | L12: Patrocinador ejecutivo | M12: IMP-006 | N12: Finalizar IMP-006 | O12: Media | P12: 1 | Q12: 46356.75 | R12: 46359.75 | S12: =NETWORKDAYS(Q12,R12) -> 4 | V12: No iniciada | W12: 0 | X12: =IF(OR(V12="Completada",V12="No aplica"),"VERDE",IF(V12="Bloqueada","ROJO",IF(R12<TODAY(),"ROJO",IF(AND(R12-TODAY()<=7,W12<1),"AMARILLO","GRIS")))) -> GRIS
A13: IMP-008 | B13: 1. Gobierno y preparación | C13: Gobierno del proyecto | D13: Inventario de sistemas fuente e interfaces | E13: Definir y aprobar: Inventario de sistemas fuente e interfaces | F13: 1) Convocar responsables de Inventario de sistemas fuente e interfaces. 2) Acordar alcance, fechas y dependencias. 3) Documentar decisión y responsable. 4) Obtener aprobación formal. 5) Archivar evidencia. | G13: Inventario de sistemas fuente e interfaces: configuración, evidencia y acta | H13: Inventario de sistemas fuente e interfaces documentado con responsable, fecha y aprobación formal. | I13: Capturas, archivo de prueba, conciliación y aprobación | J13: Todas las filiales / ajustar por ola | K13: Director de proyecto | L13: Patrocinador ejecutivo | M13: IMP-007 | N13: Finalizar IMP-007 | O13: Media | P13: 1 | Q13: 46360.75 | R13: 46364.75 | S13: =NETWORKDAYS(Q13,R13) -> 3 | V13: No iniciada | W13: 0 | X13: =IF(OR(V13="Completada",V13="No aplica"),"VERDE",IF(V13="Bloqueada","ROJO",IF(R13<TODAY(),"ROJO",IF(AND(R13-TODAY()<=7,W13<1),"AMARILLO","GRIS")))) -> GRIS
A14: IMP-009 | B14: 1. Gobierno y preparación | C14: Gobierno del proyecto | D14: Plan de calidad y evidencias | E14: Definir y aprobar: Plan de calidad y evidencias | F14: 1) Convocar responsables de Plan de calidad y evidencias. 2) Acordar alcance, fechas y dependencias. 3) Documentar decisión y responsable. 4) Obtener aprobación formal. 5) Archivar evidencia. | G14: Plan de calidad y evidencias: configuración, evidencia y acta | H14: Plan de calidad y evidencias documentado con responsable, fecha y aprobación formal. | I14: Capturas, archivo de prueba, conciliación y aprobación | J14: Todas las filiales / ajustar por ola | K14: Director de proyecto | L14: Patrocinador ejecutivo | M14: IMP-008 | N14: Finalizar IMP-008 | O14: Media | P14: 1 | Q14: 46365.75 | R14: 46367.75 | S14: =NETWORKDAYS(Q14,R14) -> 3 | V14: No iniciada | W14: 0 | X14: =IF(OR(V14="Completada",V14="No aplica"),"VERDE",IF(V14="Bloqueada","ROJO",IF(R14<TODAY(),"ROJO",IF(AND(R14-TODAY()<=7,W14<1),"AMARILLO","GRIS")))) -> GRIS
A15: IMP-010 | B15: 1. Gobierno y preparación | C15: Infraestructura y plataforma | D15: Ambientes de desarrollo, pruebas y producción | E15: Configurar y validar: Ambientes de desarrollo, pruebas y producción | F15: 1) Diseñar Ambientes de desarrollo, pruebas y producción. 2) Configurar primero en pruebas sin exponer secretos. 3) Ejecutar prueba positiva, negativa y recuperación. 4) Documentar monitoreo y rollback. 5) Promover con aprobación. | G15: Ambientes de desarrollo, pruebas y producción: configuración, evidencia y acta | H15: Ambientes de desarrollo, pruebas y producción opera en pruebas y producción, sin secretos expuestos, con monitoreo y rollback verificado. | I15: Capturas, archivo de prueba, conciliación y aprobación | J15: Todas las filiales / ajustar por ola | K15: Líder técnico | L15: TI / Seguridad | N15: Prerrequisitos del módulo | O15: Crítica | P15: 3 | Q15: 46329.75 | R15: 46335.75 | S15: =NETWORKDAYS(Q15,R15) -> 5 | V15: No iniciada | W15: 0 | X15: =IF(OR(V15="Completada",V15="No aplica"),"VERDE",IF(V15="Bloqueada","ROJO",IF(R15<TODAY(),"ROJO",IF(AND(R15-TODAY()<=7,W15<1),"AMARILLO","GRIS")))) -> GRIS
A16: IMP-011 | B16: 1. Gobierno y preparación | C16: Infraestructura y plataforma | D16: Supabase, migraciones y políticas RLS | E16: Configurar y validar: Supabase, migraciones y políticas RLS | F16: 1) Diseñar Supabase, migraciones y políticas RLS. 2) Configurar primero en pruebas sin exponer secretos. 3) Ejecutar prueba positiva, negativa y recuperación. 4) Documentar monitoreo y rollback. 5) Promover con aprobación. | G16: Supabase, migraciones y políticas RLS: configuración, evidencia y acta | H16: Supabase, migraciones y políticas RLS opera en pruebas y producción, sin secretos expuestos, con monitoreo y rollback verificado. | I16: Capturas, archivo de prueba, conciliación y aprobación | J16: Todas las filiales / ajustar por ola | K16: Líder técnico | L16: TI / Seguridad | M16: IMP-010 | N16: Finalizar IMP-010 | O16: Crítica | P16: 3 | Q16: 46336.75 | R16: 46342.75 | S16: =NETWORKDAYS(Q16,R16) -> 5 | V16: No iniciada | W16: 0 | X16: =IF(OR(V16="Completada",V16="No aplica"),"VERDE",IF(V16="Bloqueada","ROJO",IF(R16<TODAY(),"ROJO",IF(AND(R16-TODAY()<=7,W16<1),"AMARILLO","GRIS")))) -> GRIS
A17: IMP-012 | B17: 1. Gobierno y preparación | C17: Infraestructura y plataforma | D17: Railway, variables protegidas y despliegue | E17: Configurar y validar: Railway, variables protegidas y despliegue | F17: 1) Diseñar Railway, variables protegidas y despliegue. 2) Configurar primero en pruebas sin exponer secretos. 3) Ejecutar prueba positiva, negativa y recuperación. 4) Documentar monitoreo y rollback. 5) Promover con aprobación. | G17: Railway, variables protegidas y despliegue: configuración, evidencia y acta | H17: Railway, variables protegidas y despliegue opera en pruebas y producción, sin secretos expuestos, con monitoreo y rollback verificado. | I17: Capturas, archivo de prueba, conciliación y aprobación | J17: Todas las filiales / ajustar por ola | K17: Líder técnico | L17: TI / Seguridad | M17: IMP-011 | N17: Finalizar IMP-011 | O17: Media | P17: 1 | Q17: 46343.75 | R17: 46345.75 | S17: =NETWORKDAYS(Q17,R17) -> 3 | V17: No iniciada | W17: 0 | X17: =IF(OR(V17="Completada",V17="No aplica"),"VERDE",IF(V17="Bloqueada","ROJO",IF(R17<TODAY(),"ROJO",IF(AND(R17-TODAY()<=7,W17<1),"AMARILLO","GRIS")))) -> GRIS
A18: IMP-013 | B18: 1. Gobierno y preparación | C18: Infraestructura y plataforma | D18: Dominio HTTPS, Cloudflare y Turnstile | E18: Configurar y validar: Dominio HTTPS, Cloudflare y Turnstile | F18: 1) Diseñar Dominio HTTPS, Cloudflare y Turnstile. 2) Configurar primero en pruebas sin exponer secretos. 3) Ejecutar prueba positiva, negativa y recuperación. 4) Documentar monitoreo y rollback. 5) Promover con aprobación. | G18: Dominio HTTPS, Cloudflare y Turnstile: configuración, evidencia y acta | H18: Dominio HTTPS, Cloudflare y Turnstile opera en pruebas y producción, sin secretos expuestos, con monitoreo y rollback verificado. | I18: Capturas, archivo de prueba, conciliación y aprobación | J18: Todas las filiales / ajustar por ola | K18: Líder técnico | L18: TI / Seguridad | M18: IMP-012 | N18: Finalizar IMP-012 | O18: Media | P18: 1 | Q18: 46346.75 | R18: 46351.75 | S18: =NETWORKDAYS(Q18,R18) -> 4 | V18: No iniciada | W18: 0 | X18: =IF(OR(V18="Completada",V18="No aplica"),"VERDE",IF(V18="Bloqueada","ROJO",IF(R18<TODAY(),"ROJO",IF(AND(R18-TODAY()<=7,W18<1),"AMARILLO","GRIS")))) -> GRIS
A19: IMP-014 | B19: 1. Gobierno y preparación | C19: Infraestructura y plataforma | D19: SMTP y correo transaccional | E19: Configurar y validar: SMTP y correo transaccional | F19: 1) Diseñar SMTP y correo transaccional. 2) Configurar primero en pruebas sin exponer secretos. 3) Ejecutar prueba positiva, negativa y recuperación. 4) Documentar monitoreo y rollback. 5) Promover con aprobación. | G19: SMTP y correo transaccional: configuración, evidencia y acta | H19: SMTP y correo transaccional opera en pruebas y producción, sin secretos expuestos, con monitoreo y rollback verificado. | I19: Capturas, archivo de prueba, conciliación y aprobación | J19: Todas las filiales / ajustar por ola | K19: Líder técnico | L19: TI / Seguridad | M19: IMP-013 | N19: Finalizar IMP-013 | O19: Media | P19: 1 | Q19: 46352.75 | R19: 46356.75 | S19: =NETWORKDAYS(Q19,R19) -> 3 | V19: No iniciada | W19: 0 | X19: =IF(OR(V19="Completada",V19="No aplica"),"VERDE",IF(V19="Bloqueada","ROJO",IF(R19<TODAY(),"ROJO",IF(AND(R19-TODAY()<=7,W19<1),"AMARILLO","GRIS")))) -> GRIS
A20: IMP-015 | B20: 1. Gobierno y preparación | C20: Infraestructura y plataforma | D20: URLs de autenticación y recuperación | E20: Configurar y validar: URLs de autenticación y recuperación | F20: 1) Diseñar URLs de autenticación y recuperación. 2) Configurar primero en pruebas sin exponer secretos. 3) Ejecutar prueba positiva, negativa y recuperación. 4) Documentar monitoreo y rollback. 5) Promover con aprobación. | G20: URLs de autenticación y recuperación: configuración, evidencia y acta | H20: URLs de autenticación y recuperación opera en pruebas y producción, sin secretos expuestos, con monitoreo y rollback verificado. | I20: Capturas, archivo de prueba, conciliación y aprobación | J20: Todas las filiales / ajustar por ola | K20: Líder técnico | L20: TI / Seguridad | M20: IMP-014 | N20: Finalizar IMP-014 | O20: Crítica | P20: 3 | Q20: 46357.75 | R20: 46363.75 | S20: =NETWORKDAYS(Q20,R20) -> 5 | V20: No iniciada | W20: 0 | X20: =IF(OR(V20="Completada",V20="No aplica"),"VERDE",IF(V20="Bloqueada","ROJO",IF(R20<TODAY(),"ROJO",IF(AND(R20-TODAY()<=7,W20<1),"AMARILLO","GRIS")))) -> GRIS
A21: IMP-016 | B21: 1. Gobierno y preparación | C21: Infraestructura y plataforma | D21: Respaldos y restauración | E21: Configurar y validar: Respaldos y restauración | F21: 1) Diseñar Respaldos y restauración. 2) Configurar primero en pruebas sin exponer secretos. 3) Ejecutar prueba positiva, negativa y recuperación. 4) Documentar monitoreo y rollback. 5) Promover con aprobación. | G21: Respaldos y restauración: configuración, evidencia y acta | H21: Respaldos y restauración opera en pruebas y producción, sin secretos expuestos, con monitoreo y rollback verificado. | I21: Capturas, archivo de prueba, conciliación y aprobación | J21: Todas las filiales / ajustar por ola | K21: Líder técnico | L21: TI / Seguridad | M21: IMP-015 | N21: Finalizar IMP-015 | O21: Media | P21: 1 | Q21: 46364.75 | R21: 46367.75 | S21: =NETWORKDAYS(Q21,R21) -> 4 | V21: No iniciada | W21: 0 | X21: =IF(OR(V21="Completada",V21="No aplica"),"VERDE",IF(V21="Bloqueada","ROJO",IF(R21<TODAY(),"ROJO",IF(AND(R21-TODAY()<=7,W21<1),"AMARILLO","GRIS")))) -> GRIS
A22: IMP-017 | B22: 1. Gobierno y preparación | C22: Infraestructura y plataforma | D22: Monitoreo, logs y alertas | E22: Configurar y validar: Monitoreo, logs y alertas | F22: 1) Diseñar Monitoreo, logs y alertas. 2) Configurar primero en pruebas sin exponer secretos. 3) Ejecutar prueba positiva, negativa y recuperación. 4) Documentar monitoreo y rollback. 5) Promover con aprobación. | G22: Monitoreo, logs y alertas: configuración, evidencia y acta | H22: Monitoreo, logs y alertas opera en pruebas y producción, sin secretos expuestos, con monitoreo y rollback verificado. | I22: Capturas, archivo de prueba, conciliación y aprobación | J22: Todas las filiales / ajustar por ola | K22: Líder técnico | L22: TI / Seguridad | M22: IMP-016 | N22: Finalizar IMP-016 | O22: Media | P22: 1 | Q22: 46370.75 | R22: 46372.75 | S22: =NETWORKDAYS(Q22,R22) -> 3 | V22: No iniciada | W22: 0 | X22: =IF(OR(V22="Completada",V22="No aplica"),"VERDE",IF(V22="Bloqueada","ROJO",IF(R22<TODAY(),"ROJO",IF(AND(R22-TODAY()<=7,W22<1),"AMARILLO","GRIS")))) -> GRIS
A23: IMP-018 | B23: 1. Gobierno y preparación | C23: Infraestructura y plataforma | D23: Procedimiento de despliegue y rollback | E23: Configurar y validar: Procedimiento de despliegue y rollback | F23: 1) Diseñar Procedimiento de despliegue y rollback. 2) Configurar primero en pruebas sin exponer secretos. 3) Ejecutar prueba positiva, negativa y recuperación. 4) Documentar monitoreo y rollback. 5) Promover con aprobación. | G23: Procedimiento de despliegue y rollback: configuración, evidencia y acta | H23: Procedimiento de despliegue y rollback opera en pruebas y producción, sin secretos expuestos, con monitoreo y rollback verificado. | I23: Capturas, archivo de prueba, conciliación y aprobación | J23: Todas las filiales / ajustar por ola | K23: Líder técnico | L23: TI / Seguridad | M23: IMP-017 | N23: Finalizar IMP-017 | O23: Media | P23: 1 | Q23: 46373.75 | R23: 46377.75 | S23: =NETWORKDAYS(Q23,R23) -> 3 | V23: No iniciada | W23: 0 | X23: =IF(OR(V23="Completada",V23="No aplica"),"VERDE",IF(V23="Bloqueada","ROJO",IF(R23<TODAY(),"ROJO",IF(AND(R23-TODAY()<=7,W23<1),"AMARILLO","GRIS")))) -> GRIS
A24: IMP-019 | B24: 2. Fundamentos y diseño | C24: CORE | D24: Países e identificadores ISO | E24: Configurar y validar: Países e identificadores ISO | F24: 1) Levantar política para Países e identificadores ISO. 2) Preparar datos. 3) Parametrizar por filial. 4) Probar escenario normal, excepción y multimoneda cuando aplique. 5) Conciliar impacto y aprobar. | G24: Países e identificadores ISO: configuración, evidencia y acta | H24: Países e identificadores ISO funciona de extremo a extremo y contabiliza correctamente. | I24: Capturas, archivo de prueba, conciliación y aprobación | J24: Todas las filiales / ajustar por ola | K24: Líder funcional GENTIA | L24: Dueño de datos | N24: Prerrequisitos del módulo | O24: Alta | P24: 2 | Q24: 46344.75 | R24: 46349.75 | S24: =NETWORKDAYS(Q24,R24) -> 4 | V24: No iniciada | W24: 0 | X24: =IF(OR(V24="Completada",V24="No aplica"),"VERDE",IF(V24="Bloqueada","ROJO",IF(R24<TODAY(),"ROJO",IF(AND(R24-TODAY()<=7,W24<1),"AMARILLO","GRIS")))) -> GRIS
A25: IMP-020 | B25: 2. Fundamentos y diseño | C25: CORE | D25: Idiomas y zonas horarias | E25: Configurar y validar: Idiomas y zonas horarias | F25: 1) Levantar política para Idiomas y zonas horarias. 2) Preparar datos. 3) Parametrizar por filial. 4) Probar escenario normal, excepción y multimoneda cuando aplique. 5) Conciliar impacto y aprobar. | G25: Idiomas y zonas horarias: configuración, evidencia y acta | H25: Idiomas y zonas horarias funciona de extremo a extremo y contabiliza correctamente. | I25: Capturas, archivo de prueba, conciliación y aprobación | J25: Todas las filiales / ajustar por ola | K25: Líder funcional GENTIA | L25: Dueño de datos | M25: IMP-019 | N25: Finalizar IMP-019 | O25: Alta | P25: 2 | Q25: 46350.75 | R25: 46352.75 | S25: =NETWORKDAYS(Q25,R25) -> 3 | V25: No iniciada | W25: 0 | X25: =IF(OR(V25="Completada",V25="No aplica"),"VERDE",IF(V25="Bloqueada","ROJO",IF(R25<TODAY(),"ROJO",IF(AND(R25-TODAY()<=7,W25<1),"AMARILLO","GRIS")))) -> GRIS
A26: IMP-021 | B26: 2. Fundamentos y diseño | C26: CORE | D26: Monedas y precisión cambiaria | E26: Configurar y validar: Monedas y precisión cambiaria | F26: 1) Levantar política para Monedas y precisión cambiaria. 2) Preparar datos. 3) Parametrizar por filial. 4) Probar escenario normal, excepción y multimoneda cuando aplique. 5) Conciliar impacto y aprobar. | G26: Monedas y precisión cambiaria: configuración, evidencia y acta | H26: Monedas y precisión cambiaria funciona de extremo a extremo y contabiliza correctamente. | I26: Capturas, archivo de prueba, conciliación y aprobación | J26: Todas las filiales / ajustar por ola | K26: Líder funcional GENTIA | L26: Dueño de datos | M26: IMP-020 | N26: Finalizar IMP-020 | O26: Media | P26: 1 | Q26: 46353.75 | R26: 46357.75 | S26: =NETWORKDAYS(Q26,R26) -> 3 | V26: No iniciada | W26: 0 | X26: =IF(OR(V26="Completada",V26="No aplica"),"VERDE",IF(V26="Bloqueada","ROJO",IF(R26<TODAY(),"ROJO",IF(AND(R26-TODAY()<=7,W26<1),"AMARILLO","GRIS")))) -> GRIS
A27: IMP-022 | B27: 2. Fundamentos y diseño | C27: CORE | D27: Estados maestros | E27: Configurar y validar: Estados maestros | F27: 1) Levantar política para Estados maestros. 2) Preparar datos. 3) Parametrizar por filial. 4) Probar escenario normal, excepción y multimoneda cuando aplique. 5) Conciliar impacto y aprobar. | G27: Estados maestros: configuración, evidencia y acta | H27: Estados maestros funciona de extremo a extremo y contabiliza correctamente. | I27: Capturas, archivo de prueba, conciliación y aprobación | J27: Todas las filiales / ajustar por ola | K27: Líder funcional GENTIA | L27: Dueño de datos | M27: IMP-021 | N27: Finalizar IMP-021 | O27: Media | P27: 1 | Q27: 46358.75 | R27: 46363.75 | S27: =NETWORKDAYS(Q27,R27) -> 4 | V27: No iniciada | W27: 0 | X27: =IF(OR(V27="Completada",V27="No aplica"),"VERDE",IF(V27="Bloqueada","ROJO",IF(R27<TODAY(),"ROJO",IF(AND(R27-TODAY()<=7,W27<1),"AMARILLO","GRIS")))) -> GRIS
A28: IMP-023 | B28: 2. Fundamentos y diseño | C28: CORE | D28: Tipos de transacción | E28: Configurar y validar: Tipos de transacción | F28: 1) Levantar política para Tipos de transacción. 2) Preparar datos. 3) Parametrizar por filial. 4) Probar escenario normal, excepción y multimoneda cuando aplique. 5) Conciliar impacto y aprobar. | G28: Tipos de transacción: configuración, evidencia y acta | H28: Tipos de transacción funciona de extremo a extremo y contabiliza correctamente. | I28: Capturas, archivo de prueba, conciliación y aprobación | J28: Todas las filiales / ajustar por ola | K28: Líder funcional GENTIA | L28: Dueño de datos | M28: IMP-022 | N28: Finalizar IMP-022 | O28: Media | P28: 1 | Q28: 46364.75 | R28: 46366.75 | S28: =NETWORKDAYS(Q28,R28) -> 3 | V28: No iniciada | W28: 0 | X28: =IF(OR(V28="Completada",V28="No aplica"),"VERDE",IF(V28="Bloqueada","ROJO",IF(R28<TODAY(),"ROJO",IF(AND(R28-TODAY()<=7,W28<1),"AMARILLO","GRIS")))) -> GRIS
A29: IMP-024 | B29: 2. Fundamentos y diseño | C29: CORE | D29: Secuencias por filial y transacción | E29: Configurar y validar: Secuencias por filial y transacción | F29: 1) Levantar política para Secuencias por filial y transacción. 2) Preparar datos. 3) Parametrizar por filial. 4) Probar escenario normal, excepción y multimoneda cuando aplique. 5) Conciliar impacto y aprobar. | G29: Secuencias por filial y transacción: configuración, evidencia y acta | H29: Secuencias por filial y transacción funciona de extremo a extremo y contabiliza correctamente. | I29: Capturas, archivo de prueba, conciliación y aprobación | J29: Todas las filiales / ajustar por ola | K29: Líder funcional GENTIA | L29: Dueño de datos | M29: IMP-023 | N29: Finalizar IMP-023 | O29: Media | P29: 1 | Q29: 46367.75 | R29: 46371.75 | S29: =NETWORKDAYS(Q29,R29) -> 3 | V29: No iniciada | W29: 0 | X29: =IF(OR(V29="Completada",V29="No aplica"),"VERDE",IF(V29="Bloqueada","ROJO",IF(R29<TODAY(),"ROJO",IF(AND(R29-TODAY()<=7,W29<1),"AMARILLO","GRIS")))) -> GRIS
A30: IMP-025 | B30: 2. Fundamentos y diseño | C30: CORE | D30: Prefijos, longitud y consecutivo inicial | E30: Configurar y validar: Prefijos, longitud y consecutivo inicial | F30: 1) Levantar política para Prefijos, longitud y consecutivo inicial. 2) Preparar datos. 3) Parametrizar por filial. 4) Probar escenario normal, excepción y multimoneda cuando aplique. 5) Conciliar impacto y aprobar. | G30: Prefijos, longitud y consecutivo inicial: configuración, evidencia y acta | H30: Prefijos, longitud y consecutivo inicial funciona de extremo a extremo y contabiliza correctamente. | I30: Capturas, archivo de prueba, conciliación y aprobación | J30: Todas las filiales / ajustar por ola | K30: Líder funcional GENTIA | L30: Dueño de datos | M30: IMP-024 | N30: Finalizar IMP-024 | O30: Media | P30: 1 | Q30: 46372.75 | R30: 46377.75 | S30: =NETWORKDAYS(Q30,R30) -> 4 | V30: No iniciada | W30: 0 | X30: =IF(OR(V30="Completada",V30="No aplica"),"VERDE",IF(V30="Bloqueada","ROJO",IF(R30<TODAY(),"ROJO",IF(AND(R30-TODAY()<=7,W30<1),"AMARILLO","GRIS")))) -> GRIS
A31: IMP-026 | B31: 2. Fundamentos y diseño | C31: CORE | D31: Parámetros globales | E31: Configurar y validar: Parámetros globales | F31: 1) Levantar política para Parámetros globales. 2) Preparar datos. 3) Parametrizar por filial. 4) Probar escenario normal, excepción y multimoneda cuando aplique. 5) Conciliar impacto y aprobar. | G31: Parámetros globales: configuración, evidencia y acta | H31: Parámetros globales funciona de extremo a extremo y contabiliza correctamente. | I31: Capturas, archivo de prueba, conciliación y aprobación | J31: Todas las filiales / ajustar por ola | K31: Líder funcional GENTIA | L31: Dueño de datos | M31: IMP-025 | N31: Finalizar IMP-025 | O31: Media | P31: 1 | Q31: 46378.75 | R31: 46380.75 | S31: =NETWORKDAYS(Q31,R31) -> 3 | V31: No iniciada | W31: 0 | X31: =IF(OR(V31="Completada",V31="No aplica"),"VERDE",IF(V31="Bloqueada","ROJO",IF(R31<TODAY(),"ROJO",IF(AND(R31-TODAY()<=7,W31<1),"AMARILLO","GRIS")))) -> GRIS
A32: IMP-027 | B32: 2. Fundamentos y diseño | C32: CORE | D32: Configuraciones por alcance | E32: Configurar y validar: Configuraciones por alcance | F32: 1) Levantar política para Configuraciones por alcance. 2) Preparar datos. 3) Parametrizar por filial. 4) Probar escenario normal, excepción y multimoneda cuando aplique. 5) Conciliar impacto y aprobar. | G32: Configuraciones por alcance: configuración, evidencia y acta | H32: Configuraciones por alcance funciona de extremo a extremo y contabiliza correctamente. | I32: Capturas, archivo de prueba, conciliación y aprobación | J32: Todas las filiales / ajustar por ola | K32: Líder funcional GENTIA | L32: Dueño de datos | M32: IMP-026 | N32: Finalizar IMP-026 | O32: Media | P32: 1 | Q32: 46381.75 | R32: 46385.75 | S32: =NETWORKDAYS(Q32,R32) -> 3 | V32: No iniciada | W32: 0 | X32: =IF(OR(V32="Completada",V32="No aplica"),"VERDE",IF(V32="Bloqueada","ROJO",IF(R32<TODAY(),"ROJO",IF(AND(R32-TODAY()<=7,W32<1),"AMARILLO","GRIS")))) -> GRIS
A33: IMP-028 | B33: 2. Fundamentos y diseño | C33: Organización | D33: Jerarquía de subsidiarias | E33: Configurar y validar: Jerarquía de subsidiarias | F33: 1) Levantar política para Jerarquía de subsidiarias. 2) Preparar datos. 3) Parametrizar por filial. 4) Probar escenario normal, excepción y multimoneda cuando aplique. 5) Conciliar impacto y aprobar. | G33: Jerarquía de subsidiarias: configuración, evidencia y acta | H33: Jerarquía de subsidiarias funciona de extremo a extremo y contabiliza correctamente. | I33: Capturas, archivo de prueba, conciliación y aprobación | J33: Todas las filiales / ajustar por ola | K33: Consultor funcional | L33: Contabilidad corporativa | N33: Prerrequisitos del módulo | O33: Alta | P33: 2 | Q33: 46345.75 | R33: 46350.75 | S33: =NETWORKDAYS(Q33,R33) -> 4 | V33: No iniciada | W33: 0 | X33: =IF(OR(V33="Completada",V33="No aplica"),"VERDE",IF(V33="Bloqueada","ROJO",IF(R33<TODAY(),"ROJO",IF(AND(R33-TODAY()<=7,W33<1),"AMARILLO","GRIS")))) -> GRIS
A34: IMP-029 | B34: 2. Fundamentos y diseño | C34: Organización | D34: Años y calendarios fiscales | E34: Configurar y validar: Años y calendarios fiscales | F34: 1) Levantar política para Años y calendarios fiscales. 2) Preparar datos. 3) Parametrizar por filial. 4) Probar escenario normal, excepción y multimoneda cuando aplique. 5) Conciliar impacto y aprobar. | G34: Años y calendarios fiscales: configuración, evidencia y acta | H34: Años y calendarios fiscales funciona de extremo a extremo y contabiliza correctamente. | I34: Capturas, archivo de prueba, conciliación y aprobación | J34: Todas las filiales / ajustar por ola | K34: Consultor funcional | L34: Contabilidad corporativa | M34: IMP-028 | N34: Finalizar IMP-028 | O34: Alta | P34: 2 | Q34: 46351.75 | R34: 46353.75 | S34: =NETWORKDAYS(Q34,R34) -> 3 | V34: No iniciada | W34: 0 | X34: =IF(OR(V34="Completada",V34="No aplica"),"VERDE",IF(V34="Bloqueada","ROJO",IF(R34<TODAY(),"ROJO",IF(AND(R34-TODAY()<=7,W34<1),"AMARILLO","GRIS")))) -> GRIS
A35: IMP-030 | B35: 2. Fundamentos y diseño | C35: Organización | D35: Períodos contables | E35: Configurar y validar: Períodos contables | F35: 1) Levantar política para Períodos contables. 2) Preparar datos. 3) Parametrizar por filial. 4) Probar escenario normal, excepción y multimoneda cuando aplique. 5) Conciliar impacto y aprobar. | G35: Períodos contables: configuración, evidencia y acta | H35: Períodos contables funciona de extremo a extremo y contabiliza correctamente. | I35: Capturas, archivo de prueba, conciliación y aprobación | J35: Todas las filiales / ajustar por ola | K35: Consultor funcional | L35: Contabilidad corporativa | M35: IMP-029 | N35: Finalizar IMP-029 | O35: Media | P35: 1 | Q35: 46356.75 | R35: 46358.75 | S35: =NETWORKDAYS(Q35,R35) -> 3 | V35: No iniciada | W35: 0 | X35: =IF(OR(V35="Completada",V35="No aplica"),"VERDE",IF(V35="Bloqueada","ROJO",IF(R35<TODAY(),"ROJO",IF(AND(R35-TODAY()<=7,W35<1),"AMARILLO","GRIS")))) -> GRIS
A36: IMP-031 | B36: 2. Fundamentos y diseño | C36: Organización | D36: Moneda funcional y zona horaria por filial | E36: Configurar y validar: Moneda funcional y zona horaria por filial | F36: 1) Levantar política para Moneda funcional y zona horaria por filial. 2) Preparar datos. 3) Parametrizar por filial. 4) Probar escenario normal, excepción y multimoneda cuando aplique. 5) Conciliar impacto y aprobar. | G36: Moneda funcional y zona horaria por filial: configuración, evidencia y acta | H36: Moneda funcional y zona horaria por filial funciona de extremo a extremo y contabiliza correctamente. | I36: Capturas, archivo de prueba, conciliación y aprobación | J36: Todas las filiales / ajustar por ola | K36: Consultor funcional | L36: Contabilidad corporativa | M36: IMP-030 | N36: Finalizar IMP-030 | O36: Media | P36: 1 | Q36: 46359.75 | R36: 46364.75 | S36: =NETWORKDAYS(Q36,R36) -> 4 | V36: No iniciada | W36: 0 | X36: =IF(OR(V36="Completada",V36="No aplica"),"VERDE",IF(V36="Bloqueada","ROJO",IF(R36<TODAY(),"ROJO",IF(AND(R36-TODAY()<=7,W36<1),"AMARILLO","GRIS")))) -> GRIS
A37: IMP-032 | B37: 2. Fundamentos y diseño | C37: Organización | D37: Sucursales y ubicaciones | E37: Configurar y validar: Sucursales y ubicaciones | F37: 1) Levantar política para Sucursales y ubicaciones. 2) Preparar datos. 3) Parametrizar por filial. 4) Probar escenario normal, excepción y multimoneda cuando aplique. 5) Conciliar impacto y aprobar. | G37: Sucursales y ubicaciones: configuración, evidencia y acta | H37: Sucursales y ubicaciones funciona de extremo a extremo y contabiliza correctamente. | I37: Capturas, archivo de prueba, conciliación y aprobación | J37: Todas las filiales / ajustar por ola | K37: Consultor funcional | L37: Contabilidad corporativa | M37: IMP-031 | N37: Finalizar IMP-031 | O37: Media | P37: 1 | Q37: 46365.75 | R37: 46367.75 | S37: =NETWORKDAYS(Q37,R37) -> 3 | V37: No iniciada | W37: 0 | X37: =IF(OR(V37="Completada",V37="No aplica"),"VERDE",IF(V37="Bloqueada","ROJO",IF(R37<TODAY(),"ROJO",IF(AND(R37-TODAY()<=7,W37<1),"AMARILLO","GRIS")))) -> GRIS
A38: IMP-033 | B38: 2. Fundamentos y diseño | C38: Organización | D38: Tipos de departamento Cliente e Interno | E38: Configurar y validar: Tipos de departamento Cliente e Interno | F38: 1) Levantar política para Tipos de departamento Cliente e Interno. 2) Preparar datos. 3) Parametrizar por filial. 4) Probar escenario normal, excepción y multimoneda cuando aplique. 5) Conciliar impacto y aprobar. | G38: Tipos de departamento Cliente e Interno: configuración, evidencia y acta | H38: Tipos de departamento Cliente e Interno funciona de extremo a extremo y contabiliza correctamente. | I38: Capturas, archivo de prueba, conciliación y aprobación | J38: Todas las filiales / ajustar por ola | K38: Consultor funcional | L38: Contabilidad corporativa | M38: IMP-032 | N38: Finalizar IMP-032 | O38: Media | P38: 1 | Q38: 46370.75 | R38: 46372.75 | S38: =NETWORKDAYS(Q38,R38) -> 3 | V38: No iniciada | W38: 0 | X38: =IF(OR(V38="Completada",V38="No aplica"),"VERDE",IF(V38="Bloqueada","ROJO",IF(R38<TODAY(),"ROJO",IF(AND(R38-TODAY()<=7,W38<1),"AMARILLO","GRIS")))) -> GRIS
A39: IMP-034 | B39: 2. Fundamentos y diseño | C39: Organización | D39: Departamentos y jerarquía | E39: Configurar y validar: Departamentos y jerarquía | F39: 1) Levantar política para Departamentos y jerarquía. 2) Preparar datos. 3) Parametrizar por filial. 4) Probar escenario normal, excepción y multimoneda cuando aplique. 5) Conciliar impacto y aprobar. | G39: Departamentos y jerarquía: configuración, evidencia y acta | H39: Departamentos y jerarquía funciona de extremo a extremo y contabiliza correctamente. | I39: Capturas, archivo de prueba, conciliación y aprobación | J39: Todas las filiales / ajustar por ola | K39: Consultor funcional | L39: Contabilidad corporativa | M39: IMP-033 | N39: Finalizar IMP-033 | O39: Media | P39: 1 | Q39: 46373.75 | R39: 46378.75 | S39: =NETWORKDAYS(Q39,R39) -> 4 | V39: No iniciada | W39: 0 | X39: =IF(OR(V39="Completada",V39="No aplica"),"VERDE",IF(V39="Bloqueada","ROJO",IF(R39<TODAY(),"ROJO",IF(AND(R39-TODAY()<=7,W39<1),"AMARILLO","GRIS")))) -> GRIS
A40: IMP-035 | B40: 2. Fundamentos y diseño | C40: Organización | D40: Clases analíticas | E40: Configurar y validar: Clases analíticas | F40: 1) Levantar política para Clases analíticas. 2) Preparar datos. 3) Parametrizar por filial. 4) Probar escenario normal, excepción y multimoneda cuando aplique. 5) Conciliar impacto y aprobar. | G40: Clases analíticas: configuración, evidencia y acta | H40: Clases analíticas funciona de extremo a extremo y contabiliza correctamente. | I40: Capturas, archivo de prueba, conciliación y aprobación | J40: Todas las filiales / ajustar por ola | K40: Consultor funcional | L40: Contabilidad corporativa | M40: IMP-034 | N40: Finalizar IMP-034 | O40: Media | P40: 1 | Q40: 46379.75 | R40: 46381.75 | S40: =NETWORKDAYS(Q40,R40) -> 3 | V40: No iniciada | W40: 0 | X40: =IF(OR(V40="Completada",V40="No aplica"),"VERDE",IF(V40="Bloqueada","ROJO",IF(R40<TODAY(),"ROJO",IF(AND(R40-TODAY()<=7,W40<1),"AMARILLO","GRIS")))) -> GRIS
A41: IMP-036 | B41: 2. Fundamentos y diseño | C41: Organización | D41: Centros de costos | E41: Configurar y validar: Centros de costos | F41: 1) Levantar política para Centros de costos. 2) Preparar datos. 3) Parametrizar por filial. 4) Probar escenario normal, excepción y multimoneda cuando aplique. 5) Conciliar impacto y aprobar. | G41: Centros de costos: configuración, evidencia y acta | H41: Centros de costos funciona de extremo a extremo y contabiliza correctamente. | I41: Capturas, archivo de prueba, conciliación y aprobación | J41: Todas las filiales / ajustar por ola | K41: Consultor funcional | L41: Contabilidad corporativa | M41: IMP-035 | N41: Finalizar IMP-035 | O41: Media | P41: 1 | Q41: 46384.75 | R41: 46386.75 | S41: =NETWORKDAYS(Q41,R41) -> 3 | V41: No iniciada | W41: 0 | X41: =IF(OR(V41="Completada",V41="No aplica"),"VERDE",IF(V41="Bloqueada","ROJO",IF(R41<TODAY(),"ROJO",IF(AND(R41-TODAY()<=7,W41<1),"AMARILLO","GRIS")))) -> GRIS
A42: IMP-037 | B42: 2. Fundamentos y diseño | C42: Organización | D42: Acreedores financieros | E42: Configurar y validar: Acreedores financieros | F42: 1) Levantar política para Acreedores financieros. 2) Preparar datos. 3) Parametrizar por filial. 4) Probar escenario normal, excepción y multimoneda cuando aplique. 5) Conciliar impacto y aprobar. | G42: Acreedores financieros: configuración, evidencia y acta | H42: Acreedores financieros funciona de extremo a extremo y contabiliza correctamente. | I42: Capturas, archivo de prueba, conciliación y aprobación | J42: Todas las filiales / ajustar por ola | K42: Consultor funcional | L42: Contabilidad corporativa | M42: IMP-036 | N42: Finalizar IMP-036 | O42: Media | P42: 1 | Q42: 46387.75 | R42: 46392.75 | S42: =NETWORKDAYS(Q42,R42) -> 4 | V42: No iniciada | W42: 0 | X42: =IF(OR(V42="Completada",V42="No aplica"),"VERDE",IF(V42="Bloqueada","ROJO",IF(R42<TODAY(),"ROJO",IF(AND(R42-TODAY()<=7,W42<1),"AMARILLO","GRIS")))) -> GRIS
...

Sheet 03_Rollout_Filiales
A1: ROLLOUT POR FILIAL
A2: Matriz preservada del archivo de referencia, mejorada con fases y avance dinámico.
A5: ID | B5: Subsidiaria | C5: País | D5: Gobierno | E5: Maestros | F5: Seguridad | G5: Configuración | H5: Migración | I5: UAT | J5: Capacitación | K5: Cutover | L5: Estado general | M5: % preparación | N5: Go-Live | O5: Responsable | P5: Observaciones
A6: FIL-01 | B6: S.T.T. HOLDINGS LIMITED - Jamaica | D6: No iniciada | E6: No iniciada | F6: No iniciada | G6: No iniciada | H6: No iniciada | I6: No iniciada | J6: No iniciada | K6: No iniciada | L6: No iniciada | M6: =COUNTIF(D6:K6,"Completada")/8 -> 0 | N6: 46496.75
A7: FIL-02 | B7: TOTAL TALENT ECUADOR TOTAECUA S.A. - Ecuador | D7: No iniciada | E7: No iniciada | F7: No iniciada | G7: No iniciada | H7: No iniciada | I7: No iniciada | J7: No iniciada | K7: No iniciada | L7: No iniciada | M7: =COUNTIF(D7:K7,"Completada")/8 -> 0 | N7: 46496.75
A8: FIL-03 | B8: EBO, S.A. DE C.V (EL SALVADOR) | D8: No iniciada | E8: No iniciada | F8: No iniciada | G8: No iniciada | H8: No iniciada | I8: No iniciada | J8: No iniciada | K8: No iniciada | L8: No iniciada | M8: =COUNTIF(D8:K8,"Completada")/8 -> 0 | N8: 46496.75
A9: FIL-04 | B9: STT TECHNOLOGY & SOLUTIONS, INC - Panamá | D9: No iniciada | E9: No iniciada | F9: No iniciada | G9: No iniciada | H9: No iniciada | I9: No iniciada | J9: No iniciada | K9: No iniciada | L9: No iniciada | M9: =COUNTIF(D9:K9,"Completada")/8 -> 0 | N9: 46496.75
A10: FIL-05 | B10: HR SOLUTIONS PERU S.A.C. | D10: No iniciada | E10: No iniciada | F10: No iniciada | G10: No iniciada | H10: No iniciada | I10: No iniciada | J10: No iniciada | K10: No iniciada | L10: No iniciada | M10: =COUNTIF(D10:K10,"Completada")/8 -> 0 | N10: 46496.75
A11: FIL-06 | B11: PAYROLL OUTSOURCING S.A. - Costa Rica | D11: No iniciada | E11: No iniciada | F11: No iniciada | G11: No iniciada | H11: No iniciada | I11: No iniciada | J11: No iniciada | K11: No iniciada | L11: No iniciada | M11: =COUNTIF(D11:K11,"Completada")/8 -> 0 | N11: 46496.75
A12: FIL-07 | B12: INFORMATION TECHNOLOGY OUTSOURCING IN C.L.O.U.D S.A. - Costa Rica | D12: No iniciada | E12: No iniciada | F12: No iniciada | G12: No iniciada | H12: No iniciada | I12: No iniciada | J12: No iniciada | K12: No iniciada | L12: No iniciada | M12: =COUNTIF(D12:K12,"Completada")/8 -> 0 | N12: 46496.75
A13: FIL-08 | B13: STT GROUP DE CR S.A. - Costa Rica | D13: No iniciada | E13: No iniciada | F13: No iniciada | G13: No iniciada | H13: No iniciada | I13: No iniciada | J13: No iniciada | K13: No iniciada | L13: No iniciada | M13: =COUNTIF(D13:K13,"Completada")/8 -> 0 | N13: 46496.75
A14: FIL-09 | B14: STT CAPITAL DE TRABAJO SOCIEDAD ANONIMA - Costa Rica | D14: No iniciada | E14: No iniciada | F14: No iniciada | G14: No iniciada | H14: No iniciada | I14: No iniciada | J14: No iniciada | K14: No iniciada | L14: No iniciada | M14: =COUNTIF(D14:K14,"Completada")/8 -> 0 | N14: 46496.75
A15: FIL-10 | B15: SERVICE TOTAL TALENT S.A. - Costa Rica | D15: No iniciada | E15: No iniciada | F15: No iniciada | G15: No iniciada | H15: No iniciada | I15: No iniciada | J15: No iniciada | K15: No iniciada | L15: No iniciada | M15: =COUNTIF(D15:K15,"Completada")/8 -> 0 | N15: 46496.75
A16: FIL-11 | B16: STT CONSULTING, S.A. - Costa Rica | D16: No iniciada | E16: No iniciada | F16: No iniciada | G16: No iniciada | H16: No iniciada | I16: No iniciada | J16: No iniciada | K16: No iniciada | L16: No iniciada | M16: =COUNTIF(D16:K16,"Completada")/8 -> 0 | N16: 46496.75
A17: FIL-12 | B17: S.T.T. CENTROAMERICA S.A. - Costa Rica | D17: No iniciada | E17: No iniciada | F17: No iniciada | G17: No iniciada | H17: No iniciada | I17: No iniciada | J17: No iniciada | K17: No iniciada | L17: No iniciada | M17: =COUNTIF(D17:K17,"Completada")/8 -> 0 | N17: 46496.75
... A40: FIL-35 | B40: SUPPLYING TOTAL TALENT S.A.S. - Argentina | D40: No iniciada | E40: No iniciada | F40: No iniciada | G40: No iniciada | H40: No iniciada | I40: No iniciada | J40: No iniciada | K40: No iniciada | L40: No iniciada | M40: =COUNTIF(D40:K40,"Completada")/8 -> 0 | N40: 46496.75

Sheet 04_Hitos_Entregables
A1: HITOS Y ENTREGABLES
A2: Cada hito requiere evidencia y aprobación formal.
A5: ID | B5: Hito | C5: Módulo | D5: Responsable | E5: Fecha plan | F5: Fecha real | G5: Estado | H5: Aprobado por | I5: Evidencia | J5: Dependencia | K5: Criterio | L5: Observaciones
A6: H-01 | B6: Acta de inicio aprobada | C6: Programa ERP | D6: Director de proyecto | E6: 46335.75 | G6: No iniciada | J6: Acta | K6: Acta de inicio aprobada con evidencia y aprobación.
A7: H-02 | B7: Ambiente de pruebas operativo | C7: Programa ERP | D7: Director de proyecto | E7: 46351.75 | G7: No iniciada | J7: H-01 | K7: Ambiente de pruebas operativo con evidencia y aprobación.
A8: H-03 | B8: Diseño CORE y Organización aprobado | C8: Programa ERP | D8: Director de proyecto | E8: 46367.75 | G8: No iniciada | J8: H-02 | K8: Diseño CORE y Organización aprobado con evidencia y aprobación.
A9: H-04 | B9: Matriz de seguridad aprobada | C9: Programa ERP | D9: Director de proyecto | E9: 46385.75 | G9: No iniciada | J9: H-03 | K9: Matriz de seguridad aprobada con evidencia y aprobación.
A10: H-05 | B10: Plan de cuentas aprobado | C10: Programa ERP | D10: Director de proyecto | E10: 46401.75 | G10: No iniciada | J10: H-04 | K10: Plan de cuentas aprobado con evidencia y aprobación.
A11: H-06 | B11: Diseño operativo aprobado | C11: Programa ERP | D11: Director de proyecto | E11: 46419.75 | G11: No iniciada | J11: H-05 | K11: Diseño operativo aprobado con evidencia y aprobación.
A12: H-07 | B12: Ensayo de migración 1 conciliado | C12: Programa ERP | D12: Director de proyecto | E12: 46435.75 | G12: No iniciada | J12: H-06 | K12: Ensayo de migración 1 conciliado con evidencia y aprobación.
A13: H-08 | B13: Pruebas integrales completadas | C13: Programa ERP | D13: Director de proyecto | E13: 46451.75 | G13: No iniciada | J13: H-07 | K13: Pruebas integrales completadas con evidencia y aprobación.
A14: H-09 | B14: Ensayo de migración 2 conciliado | C14: Programa ERP | D14: Director de proyecto | E14: 46469.75 | G14: No iniciada | J14: H-08 | K14: Ensayo de migración 2 conciliado con evidencia y aprobación.
A15: H-10 | B15: UAT aprobada | C15: Programa ERP | D15: Director de proyecto | E15: 46485.75 | G15: No iniciada | J15: H-09 | K15: UAT aprobada con evidencia y aprobación.
A16: H-11 | B16: Capacitación completada | C16: Programa ERP | D16: Director de proyecto | E16: 46503.75 | G16: No iniciada | J16: H-10 | K16: Capacitación completada con evidencia y aprobación.
A17: H-12 | B17: Ensayo de cutover aprobado | C17: Programa ERP | D17: Director de proyecto | E17: 46519.75 | G17: No iniciada | J17: H-11 | K17: Ensayo de cutover aprobado con evidencia y aprobación.
... A20: H-15 | B20: Cierre de estabilización | C20: Programa ERP | D20: Director de proyecto | E20: 46569.75 | G20: No iniciada | J20: H-14 | K20: Cierre de estabilización con evidencia y aprobación.

Sheet 05_Migracion_Datos
A1: PLAN DE MIGRACIÓN Y CONCILIACIÓN
A2: La salida exige diferencia 0,00 y conciliación firmada.
A5: ID | B5: Objeto | C5: Módulo | D5: Fuente | E5: Propietario | F5: Plantilla | G5: Corte | H5: Volumen | I5: Reg. origen | J5: Cargados | K5: Rechazados | L5: Diferencia | M5: Ensayo 1 | N5: Ensayo 2 | O5: Carga final | P5: Conciliación | Q5: Responsable | R5: Estado | S5: Evidencia | T5: Criterio
